Workbook

Sheet DISENO_CONEXION
A1: CONEXIÓN COLUMNA - PLACA BASE AXIAL + MOMENTO
A2: Celdas amarillas = entradas editables | Celdas azules = fórmulas | Unidades base: N, kN, mm, MPa
A4: 1. DATOS GENERALES Y ENTRADAS
A5: Entrada | B5: Perfil columna | C5: HEB 500 | E5: Lista desplegable desde PERFILES | H5: Perfil W del catálogo.
A6: Entrada | B6: Fy perfil | C6: 345 | D6: MPa | E6: Acero del perfil | H6: ASTM A572 Gr.50 en el ejemplo.
A7: Entrada | B7: Ry | C7: 1.1 | D7: - | E7: Factor de sobrerresistencia esperada
A8: Entrada | B8: Fy placa base | C8: 345 | D8: MPa | E8: Acero de la placa base | H8: ASTM A36 en el ejemplo.
A9: Entrada | B9: Fu placa/arandelas | C9: 448 | D9: MPa | E9: Acero de otras placas/arandelas | H9: ASTM A572 Gr.50 en el ejemplo.
A10: Entrada | B10: f'c concreto | C10: 28 | D10: MPa | E10: Resistencia del concreto pedestal | K10: =C14+C16 -> 135
A11: Entrada | B11: phi aplastamiento | C11: 0.65 | D11: - | E11: Factor para aplastamiento en concreto
A12: Entrada | B12: B placa | C12: 700 | D12: mm | E12: Ancho de placa | H12: Dimensión transversal.
A13: Entrada | B13: N placa | C13: 800 | D13: mm | E13: Longitud de placa en eje de flexión | H13: Dimensión crítica con el momento.
A14: Entrada | B14: le borde anclaje Y | C14: 85 | D14: mm | E14: Distancia borde placa - eje anclaje
B15: le borde anclaje X | C15: 50
A16: Entrada | B16: Sobresale pedestal Y | C16: 50 | D16: mm | E16: Pedestal mayor que la placa por borde | J16: =C22/PERFILES!X3 -> 0.73786448
B17: Sobresale pedestal X | C17: 75
A18: Entrada | B18: hef anclaje | C18: 450 | D18: mm | E18: Profundidad efectiva de anclaje | H18: Desde concreto sano hasta cabeza/tuerca embebida.
A19: Entrada | B19: g grout | C19: 40 | D19: mm | E19: Espesor de grouting | K19: =C13-500 -> 300
A20: Entrada | B20: FEXX soldadura | C20: 485 | D20: MPa | E20: Electrodo de soldadura | H20: E70 aprox.
A21: Entrada | B21: H columna | C21: 2500 | D21: mm | E21: Altura libre para cortante probable | K21: =K19*0.25 -> 75
A22: Entrada | B22: Z cortante | C22: =C40 -> 4814565.7 | D22: mm³ | E22: Módulo plástico para cálculo de cortante | H22: En el ejemplo del video se usa 3.292E6 mm³. | K22: =(800-500)/2 -> 150
A23: Entrada | B23: Rigidizadores/placas laterales | C23: Sí | E23: Si Sí, gobierna m; si No, gobierna MAX(m,n) | K23: =K22-80 -> 70
A24: Entrada | B24: Modo llave de corte | C24: Automático | E24: Automático / Sí / No | H24: Automático diseña llave si los pernos no cumplen cortante+tensión+flexión. | K24: =200/25.4 -> 7.8740157
A25: Entrada | B25: b llave corte | C25: 450 | D25: mm | E25: Ancho propuesto de llave | K25: =0.45*SQRT(200000/345) -> 10.834727
A26: Entrada | B26: c llave suministrada | C26: 130 | D26: mm | E26: Altura embebida de llave
A27: Entrada | B27: t llave suministrada | C27: 50.8 | D27: mm | E27: Espesor suministrado de llave | H27: 1-3/4 pulg en el ejemplo.
A28: Entrada | B28: b arandela | C28: 90 | D28: mm | E28: Placa arandela cuadrada | J28: =382.86+50 -> 432.86
A29: Entrada | B29: t arandela | C29: 15.875 | D29: mm | E29: Espesor de placa arandela | H29: 1/2 pulg en el ejemplo.
A30: Entrada | B30: w soldadura arandela sum | C30: 6.35 | D30: mm | E30: Tamaño suministrado filete arandela | H30: 1/4 pulg en el ejemplo.
A31: Entrada | B31: b placa cabeza | C31: 90 | D31: mm | E31: Placa/tuerca de cabeza
A32: Entrada | B32: t placa cabeza | C32: 22.225 | D32: mm | E32: Espesor placa de cabeza | H32: 1 pulg en el ejemplo.
A33: 2. PROPIEDADES GEOMÉTRICAS DEL PERFIL DE COLUMNA
A34: Perfil | B34: d | C34: =IFERROR(INDEX(PERFILES!$D:$D,MATCH($C$5,PERFILES!$B:$B,0)),"") -> 500 | D34: mm | E34: INDEX/MATCH desde PERFILES
A35: Perfil | B35: bf | C35: =IFERROR(INDEX(PERFILES!$F:$F,MATCH($C$5,PERFILES!$B:$B,0)),"") -> 300 | D35: mm | E35: INDEX/MATCH desde PERFILES
A36: Perfil | B36: tw | C36: =IFERROR(INDEX(PERFILES!$E:$E,MATCH($C$5,PERFILES!$B:$B,0)),"") -> 14.5 | D36: mm | E36: INDEX/MATCH desde PERFILES
A37: Perfil | B37: tf | C37: =IFERROR(INDEX(PERFILES!$G:$G,MATCH($C$5,PERFILES!$B:$B,0)),"") -> 28 | D37: mm | E37: INDEX/MATCH desde PERFILES
A38: Perfil | B38: kdes | C38: =IFERROR(INDEX(PERFILES!$I:$I,MATCH($C$5,PERFILES!$B:$B,0)),"") -> 55 | D38: mm | E38: INDEX/MATCH desde PERFILES
A39: Perfil | B39: k1 | C39: =IFERROR(INDEX(PERFILES!$J:$J,MATCH($C$5,PERFILES!$B:$B,0)),"") -> 34.25 | D39: mm | E39: INDEX/MATCH desde PERFILES
A40: Perfil | B40: Zx columna | C40: =IFERROR(INDEX(PERFILES!$X:$X,MATCH($C$5,PERFILES!$B:$B,0)),"") -> 4814565.7 | D40: mm³ | E40: INDEX/MATCH desde PERFILES
A41: Geometría | B41: m voladizo | C41: =($C$13-0.95*$C$34)/2 -> 162.5 | D41: mm | E41: (N - 0.95 d)/2
...

Sheet PERFILES
A1: ID | B1: Sección | C1: A tabla | D1: d | E1: tw | F1: bf | G1: tf | H1: k dis | I1: k det | J1: k1 | K1: T | L1: wg | M1: R | N1: A calc | O1: h0 | P1: alfa1 | Q1: D1 | R1: Ix | S1: Iy | T1: rx | U1: ry | V1: Sx | W1: Sy | X1: Zx | Y1: Zy | Z1: J | AA1: Cw | AB1: rts | AC1: Delta A
A2: - | B2: - | C2: [mm²] | D2: [mm] | E2: [mm] | F2: [mm] | G2: [mm] | H2: [mm] | I2: [mm] | J2: [mm] | K2: [mm] | L2: [mm] | M2: [mm] | N2: [mm²] | O2: [mm] | P2: [-] | Q2: [mm] | R2: [mm^4] | S2: [mm^4] | T2: [mm] | U2: [mm] | V2: [mm^3] | W2: [mm^3] | X2: [mm^3] | Y2: [mm^3] | Z2: [mm^4] | AA2: [mm^6] | AB2: [mm] | AC2: [%]
A3: 0 | B3: W18X175 | D3: 509 | E3: 22.6 | F3: 289 | G3: 40.4 | H3: 50.55 | I3: 50.55 | J3: 31.75 | X3: 6525000
A4: 1 | B4: IPE 80 | C4: 764.34 | D4: 80 | E4: 3.8 | F4: 46 | G4: 5.2 | H4: 10.2 | I4: 15 | J4: 6.9 | K4: 50 | L4: 16.1 | M4: 5 | N4: 764.34 | O4: 74.8 | P4: 0.15004142 | Q4: 8.3322368 | R4: 801376.37 | S4: 84890.189 | T4: 32.37986 | U4: 10.538662 | V4: 20034.409 | W4: 3690.8778 | X4: 23216.953 | Y4: 5817.5974 | Z4: 6724.3184 | AA4: 1.1799641e+08 | AB4: 12.588567 | AC4: 0
A5: 2 | B5: IPE 100 | C5: 1032.3216 | D5: 100 | E5: 4.1 | F5: 55 | G5: 5.7 | H5: 12.7 | I5: 15 | J5: 9.05 | K5: 70 | L5: 18.45 | M5: 7 | N5: 1032.3216 | O5: 94.3 | P5: 0.16934272 | Q5: 9.8574873 | R5: 1710120.2 | S5: 159186.38 | T5: 40.701069 | U5: 12.417823 | V5: 34202.404 | W5: 5788.5958 | X5: 39406.821 | Y5: 9145.5843 | Z5: 11580.399 | AA5: 3.5137841e+08 | AB5: 14.813766 | AC5: 0
A6: 3 | B6: IPE 120 | C6: 1321.0216 | D6: 120 | E6: 4.4 | F6: 64 | G6: 6.3 | H6: 13.3 | I6: 15 | J6: 9.2 | K6: 90 | L6: 22.8 | M6: 7 | N6: 1321.0216 | O6: 113.7 | P6: 0.16027261 | Q6: 10.469458 | R6: 3177532.5 | S6: 276681.41 | T6: 49.044469 | U6: 14.472216 | V6: 52958.875 | W6: 8646.294 | X6: 60725.017 | Y6: 13580.518 | Z6: 16907.747 | AA6: 8.8959055e+08 | AB6: 17.233991 | AC6: 0
A7: 4 | B7: IPE 140 | C7: 1642.6016 | D7: 140 | E7: 4.7 | F7: 73 | G7: 6.9 | H7: 13.9 | I7: 15 | J7: 9.35 | K7: 110 | L7: 27.15 | M7: 7 | N7: 1642.6016 | O7: 133.1 | P7: 0.15241346 | Q7: 11.082895 | R7: 5412238.6 | S7: 449177.67 | T7: 57.401382 | U7: 16.536476 | V7: 77317.695 | W7: 12306.238 | X7: 88344.357 | Y7: 19246.601 | Z7: 24001.936 | AA7: 1.9813561e+09 | AB7: 19.662723 | AC7: 0
A8: 5 | B8: IPE 160 | C8: 2009.1304 | D8: 160 | E8: 5 | F8: 82 | G8: 7.4 | H8: 16.4 | I8: 20 | J8: 11.5 | K8: 120 | L8: 29.5 | M8: 9 | N8: 2009.1304 | O8: 152.6 | P8: 0.16787217 | Q8: 12.606693 | R8: 8692925.1 | S8: 683144.31 | T8: 65.777734 | U8: 18.439628 | V8: 108661.56 | W8: 16662.056 | X8: 123859.61 | Y8: 26099.904 | Z8: 35423.152 | AA8: 3.9588687e+09 | AB8: 21.901836 | AC8: -1.1317019e-16
A9: 6 | B9: IPE 180 | C9: 2394.7304 | D9: 180 | E9: 5.3 | F9: 91 | G9: 8 | H9: 17 | I9: 20 | J9: 11.65 | K9: 140 | L9: 33.85 | M9: 9 | N9: 2394.7304 | O9: 172 | P9: 0.16045977 | Q9: 13.220096 | R9: 13169585 | S9: 1008502.9 | T9: 74.157952 | U9: 20.521555 | V9: 146328.72 | W9: 22164.899 | X9: 166414.92 | Y9: 34599.723 | Z9: 47282.072 | AA9: 7.4312148e+09 | AB9: 24.345742 | AC9: 0
A10: 7 | B10: IPE 200 | C10: 2848.4096 | D10: 200 | E10: 5.6 | F10: 100 | G10: 8.5 | H10: 20.5 | I10: 25 | J10: 14.8 | K10: 150 | L10: 35.2 | M10: 12 | N10: 2848.4096 | O10: 191.5 | P10: 0.18301869 | Q10: 15.239692 | R10: 19431670 | S10: 1423679.5 | T10: 82.595017 | U10: 22.356556 | V10: 194316.7 | W10: 28473.59 | X10: 220638.55 | Y10: 44612.152 | Z10: 69205.593 | AA10: 1.2988089e+10 | AB10: 26.486248 | AC10: 0
A11: 8 | B11: IPE 220 | C11: 3337.0496 | D11: 220 | E11: 5.9 | F11: 110 | G11: 9.2 | H11: 21.2 | I11: 25 | J11: 14.95 | K11: 170 | L11: 40.05 | M11: 12 | N11: 3337.0496 | O11: 210.8 | P11: 0.17430523 | Q11: 15.932003 | R11: 27718374 | S11: 2048857.7 | T11: 91.13864 | U11: 24.778475 | V11: 251985.22 | W11: 37251.959 | X11: 285405.9 | Y11: 58110.397 | Z11: 90357.036 | AA11: 2.2672314e+10 | AB11: 29.274445 | AC11: 0
A12: 9 | B12: IPE 240 | C12: 3911.62 | D12: 240 | E12: 6.2 | F12: 120 | G12: 9.8 | H12: 24.8 | I12: 25 | J12: 18.1 | K12: 190 | L12: 41.9 | M12: 15 | N12: 3911.62 | O12: 230.2 | P12: 0.19256685 | Q12: 18.031407 | R12: 38916234 | S12: 2836332.4 | T12: 99.744068 | U12: 26.927761 | V12: 324301.95 | W12: 47272.207 | X12: 366645.16 | Y12: 73923.897 | Z12: 129643.28 | AA12: 37391183424 | AB12: 31.727909 | AC12: 0
A13: 10 | B13: IPE 270 | C13: 4594.5 | D13: 270 | E13: 6.6 | F13: 135 | G13: 10.2 | H13: 25.2 | I13: 30 | J13: 18.3 | K13: 210 | L13: 49.2 | M13: 15 | N13: 4594.5 | O13: 259.8 | P13: 0.18768858 | Q13: 18.530597 | R13: 57897796 | S13: 4198678.6 | T13: 112.2566 | U13: 30.229933 | V13: 428872.56 | W13: 62202.646 | X13: 483996.62 | Y13: 96950.125 | Z13: 159143.61 | AA13: 7.0577867e+10 | AB13: 35.661266 | AC13: 0
A14: 11 | B14: IPE 300 | C14: 5381.2 | D14: 300 | E14: 7.1 | F14: 150 | G14: 10.7 | H14: 25.7 | I14: 30 | J14: 18.55 | K14: 240 | L14: 56.45 | M14: 15 | N14: 5381.2 | O14: 289.3 | P14: 0.18225037 | Q14: 19.154607 | R14: 83561052 | S14: 6037775 | T14: 124.61272 | U14: 33.496459 | V14: 557073.68 | W14: 80503.667 | X14: 628355.66 | Y14: 125218.82 | Z14: 199304.17 | AA14: 1.2593405e+11 | AB14: 39.595093 | AC14: 0
A15: 12 | B15: IPE 330 | C15: 6260.6216 | D15: 330 | E15: 7.5 | F15: 160 | G15: 11.5 | H15: 29.5 | I15: 30 | J15: 21.75 | K15: 270 | L15: 58.25 | M15: 18 | N15: 6260.6216 | O15: 318.5 | P15: 0.19521267 | Q15: 21.459211 | R15: 1.1766898e+08 | S15: 7881402.6 | T15: 137.0952 | U15: 35.480769 | V15: 713145.3 | W15: 98517.533 | X15: 804330.32 | Y15: 153678.37 | Z15: 280845.59 | AA15: 1.9909732e+11 | AB15: 41.95198 | AC15: 0
... A125: 122 | B125: HP400X231 | C125: 27857.14 | D125: 372 | E125: 26 | F125: 372 | G125: 26 | H125: 41 | I125: 45 | J125: 28 | K125: 282 | L125: 158 | M125: 15 | N125: 27857.14 | O125: 346 | P125: 0.13405769 | Q125: 40 | R125: 6.5577461e+08 | S125: 2.2359685e+08 | T125: 153.42956 | U125: 89.591041 | V125: 3525670 | W125: 1202133.6 | X125: 4042367.3 | Y125: 1856229.9 | Z125: 6728066.8 | AA125: 6676411914432 | AB125: 104.74543 | AC125: 0

Sheet CATALOGOS
A1: d_a mm | B1: Etiqueta | C1: d_a pulg | D1: n_t hilos/pulg | E1: d_h arandela mm | F1: d_h base mm | G1: F tuerca mm | I1: t mm | J1: pulgadas | K1: Etiqueta | M1: Barra | N1: d_b mm | O1: Área cm² | Q1: Sí/No | S1: Modo llave | U1: Ancho arandela mm | W1: Tamaño soldadura mm | Y1: Material | Z1: Fy MPa | AA1: Fu MPa
A2: 19.05 | B2: 3/4" | C2: 0.75 | D2: 10 | E2: 20.64 | F2: 34.93 | G2: 28.58 | I2: 6.35 | J2: 0.25 | K2: 1/4" | M2: N2 | N2: 6.35 | O2: 0.31669217 | Q2: Sí | S2: Automático | U2: 75 | W2: 3 | Y2: ASTM A36 | Z2: 248 | AA2: 410
A3: 22.225 | B3: 7/8" | C3: 0.875 | D3: 9 | E3: 23.81 | F3: 38.1 | G3: 33.34 | I3: 8 | J3: 0.315 | K3: 5/16" aprox. | M3: N3 | N3: 9.525 | O3: 0.71255739 | Q3: No | S3: Sí | U3: 80 | W3: 4.8 | Y3: ASTM A572 Gr.50 | Z3: 345 | AA3: 448
A4: 25.4 | B4: 1" | C4: 1 | D4: 8 | E4: 27 | F4: 41.28 | G4: 38.1 | I4: 9.525 | J4: 0.375 | K4: 3/8" | M4: N4 | N4: 12.7 | O4: 1.2667687 | S4: No | U4: 90 | W4: 6.35 | Y4: F1554 Gr.105 | AA4: 840
A5: 28.575 | B5: 1 1/8" | C5: 1.125 | D5: 7 | E5: 30.16 | F5: 47.63 | G5: 42.86 | I5: 12.7 | J5: 0.5 | K5: 1/2" | M5: N5 | N5: 15.875 | O5: 1.9793261 | U5: 100 | W5: 8 | Y5: Refuerzo Gr.60 | Z5: 420
A6: 31.75 | B6: 1 1/4" | C6: 1.25 | D6: 7 | E6: 34.34 | F6: 53.98 | G6: 47.63 | I6: 15.875 | J6: 0.625 | K6: 5/8" | M6: N6 | N6: 19.05 | O6: 2.8502296 | U6: 110 | W6: 9.5
A7: 34.925 | B7: 1 3/8" | C7: 1.375 | D7: 6 | E7: 38.1 | F7: 57.15 | G7: 52.39 | I7: 19.05 | J7: 0.75 | K7: 3/4" | M7: N7 | N7: 22.225 | O7: 3.8794791 | U7: 120 | W7: 12.7
A8: 38.1 | B8: 1 1/2" | C8: 1.5 | D8: 6 | E8: 41.28 | F8: 63.5 | G8: 57.15 | I8: 22.225 | J8: 0.875 | K8: 7/8" | M8: N8 | N8: 25.4 | O8: 5.0670748 | U8: 150 | W8: 16
A9: 44.45 | B9: 1 3/4" | C9: 1.75 | D9: 5 | E9: 47.63 | F9: 69.85 | G9: 66.68 | I9: 25.4 | J9: 1 | K9: 1" | M9: N9 | N9: 28.65 | O9: 6.4467248
A10: 50.8 | B10: 2" | C10: 2 | D10: 4.5 | E10: 53.98 | F10: 76.2 | G10: 76.2 | I10: 31.75 | J10: 1.25 | K10: 1 1/4" | M10: N10 | N10: 32.26 | O10: 8.1736984
I11: 38.1 | J11: 1.5 | K11: 1 1/2"
I12: 44.45 | J12: 1.75 | K12: 1 3/4"
I13: 50.8 | J13: 2 | K13: 2"
I14: 57.15 | J14: 2.25 | K14: 2 1/4"
I15: 63.5 | J15: 2.5 | K15: 2 1/2"
I16: 76.2 | J16: 3 | K16: 3"
I17: 88.9 | J17: 3.5 | K17: 3 1/2"
I18: 101.6 | J18: 4 | K18: 4"

Sheet INSTRUCCIONES
A1: PROGRAMACIÓN - CONEXIÓN COLUMNA / PLACA BASE AXIAL + MOMENTO
A2: Alcance | B2: Hoja paramétrica vertical para placa base, anclajes, pedestal, arrancamiento, cortante, llave de corte, arandelas y soldaduras, basada en las imágenes y transcripción del procedimiento AISC 341-16 / Guía No. 1 AISC / ACI 318.
A3: Uso | B3: Cambie únicamente las celdas de entrada en amarillo en la hoja DISENO_CONEXION. Las celdas azules contienen fórmulas.
A4: Catálogos | B4: PERFILES contiene el catálogo importado del Excel adjunto y se agregó W18X175 con propiedades del ejemplo de las imágenes. CATALOGOS contiene diámetros, espesores, barras y listas desplegables.
A5: Nota técnica | B5: Las fórmulas están escritas en sintaxis estándar de Excel. En Excel en español se mostrarán/localizarán según la configuración regional.
A6: Advertencia | B6: Revise normas aplicables, unidades, detalles constructivos, borde/espaciamiento de anclajes, soldaduras CJP y compatibilidad con planos antes de usar en diseño definitivo.
